============================= test session starts ==============================
platform linux -- Python 3.10.6, pytest-8.3.5, pluggy-1.5.0 -- /home/elias/.pyenv/versions/3.10.6/envs/taxifare-env/bin/python
cachedir: .pytest_cache
rootdir: /home/elias/code/Elias0512vs/07-ML-Ops/04-Predict-in-production/data-fast-api/tests
configfile: pytest_kitt.ini
plugins: asyncio-0.26.0, anyio-3.7.1, time-machine-2.16.0
asyncio: mode=strict, asyncio_default_fixture_loop_scope=None, asyncio_default_test_loop_scope=function
collecting ... collected 12 items / 1 error

==================================== ERRORS ====================================
________________ ERROR collecting api/test_docker_endpoints.py _________________
tests/api/test_docker_endpoints.py:27: in <module>
    docker_port = re.findall(":(\d{4})-", docker_ps_output)[0]
E   IndexError: list index out of range
=========================== short test summary info ============================
ERROR tests/api/test_docker_endpoints.py - IndexError: list index out of range
!!!!!!!!!!!!!!!!!!!! Interrupted: 1 error during collection !!!!!!!!!!!!!!!!!!!!
========================= 1 warning, 1 error in 0.33s ==========================
